Workbook

Sheet Okładka
B3: BERSERK RUSH
B4: Katalog Mechanik Gry — Analiza katalogu docs/
B6: Wygenerowano: 2026-08-03 • Źródło: C:\dev\berserk-rush\docs\ (26 modułów + roadmapa)
B9: Zawartość skoroszytu
B10: Przegląd Modułów | C10: Lista 26 modułów gry z kategorią, typem mechaniki, wymaganym poziomem i opisem.
B11: Wszystkie Mechaniki | C11: Indeks ~148 nazwanych mechanik/podsystemów wraz z typem (liczbowa/tekstowa/mieszana) i opisem.
B12: Parametry Liczbowe | C12: Płaska tabela ~150 wyekstrahowanych wartości liczbowych (limity, szanse, formuły, koszty).
B13: Reguły Tekstowe | C13: Tabela ~75 reguł jakościowych/projektowych (blokady, procesy, zasady balansu, zapisy prawne).
B14: Poziomy i Progresja | C14: Bramki poziomowe, krzywa wymaganego XP (formuła) i punkty postaci/umiejętności.
B15: Walka - Parametry | C15: Twarde limity walki, skalowanie potworów, wagi atrybutów wg broni, formuły HP/Many.
B16: Ekonomia i Ceny | C16: Opłaty rynkowe, koszty zwojów, dostępu do Lustra i kosztów zaklęć.
B17: Pety | C17: Tiery, macierz wyklucia, szanse i koszty fuzji, warianty porażki fuzji.
B18: Rzemiosło i Ulepszenia | C18: Rzadkość craftingu, krzywa szans zaklęć, mikstury, ulepszanie +0..+9.
B19: Nagrody Cykliczne | C19: Rankingi tygodniowe i nagrody World Bossa wg miejsca w rankingu.
B20: Dungeony i Multi | C20: Skalowanie trudności i nagród w trybie Multi-Dungeon (1x/3x/5x).
B21: Roadmapa | C21: Status 18 faz rozwoju gry (zakończone / planowane).
B23: Metodologia: wszystkie wartości liczbowe i reguły odtworzone bezpośrednio z treści plików docs/*.md i docs/modules/*.md (26 plików). Tam, gdzie dokumentacja nie podaje dokładnej liczby (np. pełna krzywa szans ulepszania +2..+9), zaznaczono to wprost w arkuszu zamiast zgadywać.

Sheet Przegląd Modułów
A1: Przegląd Modułów
A2: 26 modułów gry Berserk Rush — kategoria, typ mechaniki, wymagany poziom i liczba udokumentowanych mechanik
A4: Moduł | B4: Kategoria | C4: Typ Mechaniki | D4: Wymagany poziom | E4: Liczba mechanik | F4: Parametry liczbowe | G4: Reguły tekstowe | H4: Krótki opis
A5: Achievements & Kolekcje | B5: Systemy Dodatkowe | C5: Mieszana | D5: - | E5: =COUNTIF('Wszystkie Mechaniki'!$A:$A,A5) -> 6 | F5: =COUNTIF('Parametry Liczbowe'!$A:$A,A5) -> 0 | G5: =COUNTIF('Reguły Tekstowe'!$A:$A,A5) -> 4 | H5: Osiągnięcia, Bestiariusz i Tytuły napędzane eventami, dające długoterminowe cele (endgame retention).
A6: Kowal (Blacksmith) | B6: Ekonomia i Rzemiosło | C6: Mieszana | D6: - | E6: =COUNTIF('Wszystkie Mechaniki'!$A:$A,A6) -> 5 | F6: =COUNTIF('Parametry Liczbowe'!$A:$A,A6) -> 0 | G6: =COUNTIF('Reguły Tekstowe'!$A:$A,A6) -> 2 | H6: Zunifikowana domena ulepszania (+0..+9) i craftingu broni/zbroi, scalona z dawnych Weaponsmith/Armorsmith.
A7: Postacie (Characters) | B7: Postać i Progresja | C7: Mieszana | D7: - | E7: =COUNTIF('Wszystkie Mechaniki'!$A:$A,A7) -> 4 | F7: =COUNTIF('Parametry Liczbowe'!$A:$A,A7) -> 6 | G7: =COUNTIF('Reguły Tekstowe'!$A:$A,A7) -> 4 | H7: Tworzenie postaci, przydział atrybutów startowych, system poziomów i XP.
A8: Walka (Combat) | B8: Walka (PvE) | C8: Liczbowa | D8: - | E8: =COUNTIF('Wszystkie Mechaniki'!$A:$A,A8) -> 11 | F8: =COUNTIF('Parametry Liczbowe'!$A:$A,A8) -> 30 | G8: =COUNTIF('Reguły Tekstowe'!$A:$A,A8) -> 5 | H8: Asynchroniczny, turowy silnik walki PvE: inicjatywa, krytyki, uniki, obrażenia, specjalizacje broni.
A9: Dungeony | B9: Walka (PvE) | C9: Mieszana | D9: wg lochu | E9: =COUNTIF('Wszystkie Mechaniki'!$A:$A,A9) -> 7 | F9: =COUNTIF('Parametry Liczbowe'!$A:$A,A9) -> 5 | G9: =COUNTIF('Reguły Tekstowe'!$A:$A,A9) -> 3 | H9: Instancjonowane, etapowe PvE z kumulacją łupu i trybem Multi-Dungeon (1x/3x/5x).
A10: Gospodarka i Market | B10: Ekonomia i Rzemiosło | C10: Liczbowa | D10: - | E10: =COUNTIF('Wszystkie Mechaniki'!$A:$A,A10) -> 7 | F10: =COUNTIF('Parametry Liczbowe'!$A:$A,A10) -> 5 | G10: =COUNTIF('Reguły Tekstowe'!$A:$A,A10) -> 3 | H10: Handel graczy: wystawianie ofert, opłaty, prowizje, filtrowanie rynku.
A11: Globalny Czat | B11: Społeczność | C11: Mieszana | D11: - | E11: =COUNTIF('Wszystkie Mechaniki'!$A:$A,A11) -> 7 | F11: =COUNTIF('Parametry Liczbowe'!$A:$A,A11) -> 8 | G11: =COUNTIF('Reguły Tekstowe'!$A:$A,A11) -> 4 | H11: Wielokanałowy czat real-time (Reverb/WebSockets) z integracją Discord.
A12: Gildie | B12: Społeczność | C12: Mieszana | D12: 10 | E12: =COUNTIF('Wszystkie Mechaniki'!$A:$A,A12) -> 6 | F12: =COUNTIF('Parametry Liczbowe'!$A:$A,A12) -> 6 | G12: =COUNTIF('Reguły Tekstowe'!$A:$A,A12) -> 4 | H12: Zrzeszanie graczy, skarbiec, role, Wojny Gildii 5v5.
A13: Sklep Premium (Item Shop) | B13: Ekonomia i Rzemiosło | C13: Liczbowa | D13: - | E13: =COUNTIF('Wszystkie Mechaniki'!$A:$A,A13) -> 4 | F13: =COUNTIF('Parametry Liczbowe'!$A:$A,A13) -> 7 | G13: =COUNTIF('Reguły Tekstowe'!$A:$A,A13) -> 3 | H13: Zakup Gemów (Stripe), status Premium i Zwoje Użytkowe.
A14: Łupy (Loot) | B14: Walka (PvE) | C14: Liczbowa | D14: - | E14: =COUNTIF('Wszystkie Mechaniki'!$A:$A,A14) -> 6 | F14: =COUNTIF('Parametry Liczbowe'!$A:$A,A14) -> 3 | G14: =COUNTIF('Reguły Tekstowe'!$A:$A,A14) -> 2 | H14: Tabele zrzutów, Weighted Picker, balans wag dropu materiałów/przedmiotów.
A15: Poczta (Mail) | B15: Techniczne / Meta | C15: Tekstowa | D15: - | E15: =COUNTIF('Wszystkie Mechaniki'!$A:$A,A15) -> 4 | F15: =COUNTIF('Parametry Liczbowe'!$A:$A,A15) -> 1 | G15: =COUNTIF('Reguły Tekstowe'!$A:$A,A15) -> 2 | H15: Asynchroniczny kanał System -> Gracz z załącznikami walut/przedmiotów.
A16: Handlarz (Merchant) | B16: Ekonomia i Rzemiosło | C16: Mieszana | D16: - | E16: =COUNTIF('Wszystkie Mechaniki'!$A:$A,A16) -> 6 | F16: =COUNTIF('Parametry Liczbowe'!$A:$A,A16) -> 4 | G16: =COUNTIF('Reguły Tekstowe'!$A:$A,A16) -> 2 | H16: Zunifikowany NPC kupna/sprzedaży ekwipunku, asortyment w tierach poziomowych.
... A30: Światowy Boss (World Boss) | B30: Walka (PvE) | C30: Liczbowa | D30: - | E30: =COUNTIF('Wszystkie Mechaniki'!$A:$A,A30) -> 7 | F30: =COUNTIF('Parametry Liczbowe'!$A:$A,A30) -> 11 | G30: =COUNTIF('Reguły Tekstowe'!$A:$A,A30) -> 4 | H30: 3 współdzielone instancje bossów (low/mid/high) ze wspólną, niemalejącą pulą HP.

Sheet Wszystkie Mechaniki
A1: Wszystkie Mechaniki
A2: Indeks każdej nazwanej mechaniki/podsystemu opisanego w docs/modules/*.md
A4: Moduł | B4: Nr | C4: Nazwa Mechaniki | D4: Typ | E4: Opis
A5: Achievements & Kolekcje | B5: 1 | C5: Wydarzenia i Nasłuchiwanie | D5: Tekstowa | E5: Cały system napędzany asynchronicznymi eventami (MonsterDefeated -> AchievementProgressed -> toast UI).
A6: Achievements & Kolekcje | B6: 2 | C6: Tabele w Bazie Danych | D6: Tekstowa | E6: achievements/character_achievements/titles/character_titles - słowniki i powiązania many-to-many.
A7: Achievements & Kolekcje | B7: 3 | C7: Księga Osiągnięć | D7: Mieszana | E7: Osiągnięcia z 'Parent ID' tworzą łańcuchy trudności (Tier I/II), nagradzają punktami/złotem/tytułem/przedmiotem.
A8: Achievements & Kolekcje | B8: 4 | C8: Tytuły i Reprezentacja | D8: Tekstowa | E8: Gracz wybiera 1 zdobyty tytuł jako stały prefiks na czacie, z pasywnymi bonusami statystyk.
A9: Achievements & Kolekcje | B9: 5 | C9: Zbieractwo Kontekstowe (Enumy) | D9: Tekstowa | E9: MonsterType/MonsterRank przekazywane jako kontekst, by warunki JSON trafiały tylko właściwe zdarzenia.
A10: Achievements & Kolekcje | B10: 6 | C10: Panel Administratora | D10: Tekstowa | E10: GUI do tworzenia osiągnięć, warunków i nagród bez pisania kodu.
A11: Kowal (Blacksmith) | B11: 1 | C11: Unifikacja Domeny | D11: Tekstowa | E11: Scalenie funkcjonalności Weaponsmith i Armorsmith w jeden widok Kowala.
A12: Kowal (Blacksmith) | B12: 2 | C12: Zakładka Kuźnia Ulepszeń | D12: Mieszana | E12: Lista przedmiotów do ulepszenia (weapon/armor) z kosztami i szansą powodzenia.
A13: Kowal (Blacksmith) | B13: 3 | C13: Zakładka Rzemiosło | D13: Mieszana | E13: Receptury (ItemRecipe) dla broni/zbroi, wspólny CraftingService z Wiedźmą.
A14: Kowal (Blacksmith) | B14: 4 | C14: Filtr Typu/Slotu | D14: Tekstowa | E14: 5 filtrów (Wszystko/Broń/Hełmy/Zbroje/Buty) działających spójnie na obu zakładkach.
A15: Kowal (Blacksmith) | B15: 5 | C15: Podpowiedzi Materiałów | D15: Tekstowa | E15: Tooltip pokazuje z jakich potworów i map zdobyć dany surowiec.
A16: Postacie (Characters) | B16: 1 | C16: Tworzenie Postaci | D16: Liczbowa | E16: Max 4 postacie/konto, 10 punktów startowych na 4 atrybuty (zakres 0-10), broń startowa.
... A152: Światowy Boss (World Boss) | B152: 7 | C152: Nagrody | D152: Liczbowa | E152: Gemy i klucze do lochów wg miejsca w rankingu Top 10.

Sheet Parametry Liczbowe
A1: Parametry Liczbowe
A2: Każda wartość liczbowa (limit, szansa, koszt, formuła) wyekstrahowana z dokumentacji
A4: Moduł | B4: Mechanika | C4: Parametr | D4: Wartość | E4: Jednostka / Zakres | F4: Uwagi
A5: Postacie (Characters) | B5: Tworzenie postaci | C5: Maksymalna liczba postaci na konto | D5: 4 | E5: szt. | F5: Twardy limit na konto
A6: Postacie (Characters) | B6: Tworzenie postaci | C6: Punkty początkowe do rozdania | D6: 10 | E6: pkt | F6: Na 4 atrybuty: STR/INT/VIT/AGI
A7: Postacie (Characters) | B7: Tworzenie postaci | C7: Zakres atrybutu startowego | D7: 0-10 | E7: pkt/atrybut | F7: Losowanie początkowe
A8: Postacie (Characters) | B8: Poziomy i XP | C8: Punkty postaci za poziom | D8: 3 | E8: pkt/poziom | F8: character_points
A9: Postacie (Characters) | B9: Poziomy i XP | C9: Maksymalny poziom postaci | D9: 99 | E9: poziom | F9: LevelUpService::MAX_LEVEL
A10: Postacie (Characters) | B10: Poziomy i XP | C10: Budżet punktów postaci na poz. 99 | D10: 304 | E10: pkt | F10: 10 + 98*3
A11: Walka (Combat) | B11: Symulacja walki | C11: Maksymalna liczba tur | D11: 50 | E11: tur
A12: Walka (Combat) | B12: Trafienie krytyczne | C12: Szansa za punkt AGI | D12: 0.15 | E12: %/pkt AGI
A13: Walka (Combat) | B13: Trafienie krytyczne | C13: Hard cap - gracz | D13: 100 | E13: %
A14: Walka (Combat) | B14: Trafienie krytyczne | C14: Hard cap - potwór | D14: 30 | E14: %
A15: Walka (Combat) | B15: Trafienie krytyczne | C15: Mnożnik obrażeń | D15: 1.5 | E15: x
A16: Walka (Combat) | B16: Unik (dodge) | C16: Hard cap uniku | D16: 30 | E16: % | F16: Gracz i potwór
A17: Walka (Combat) | B17: Obrażenia | C17: Redukcja za punkt obrony | D17: 0.2 | E17: dmg/pkt DEF
A18: Walka (Combat) | B18: Skalowanie potworów | C18: Wzrost staty za poziom różnicy | D18: 10 | E18: %/poziom | F18: multiplier = 1+(diff*0.10)
A19: Walka (Combat) | B19: HP gracza | C19: Baza HP | D19: 100 | E19: pkt | F19: 100 + VIT*15 + poziom*5
A20: Walka (Combat) | B20: HP gracza | C20: HP za punkt VIT | D20: 15 | E20: pkt/VIT
A21: Walka (Combat) | B21: HP gracza | C21: HP za poziom | D21: 5 | E21: pkt/poziom
A22: Walka (Combat) | B22: Mana gracza | C22: Baza many | D22: 50 | E22: pkt | F22: 50 + INT*10 + poziom*3
A23: Walka (Combat) | B23: Mana gracza | C23: Mana za punkt INT | D23: 10 | E23: pkt/INT
A24: Walka (Combat) | B24: Mana gracza | C24: Mana za poziom | D24: 3 | E24: pkt/poziom
A25: Walka (Combat) | B25: Rasy potworów | C25: Liczba głównych ras | D25: 6 | E25: szt. | F25: undead/demon/animal/orc/troll/mystical
A26: Walka (Combat) | B26: Otrucie z procka (afiks) | C26: Czas trwania | D26: 3 | E26: tury
A27: Walka (Combat) | B27: Otrucie z procka (afiks) | C27: Obrażenia na turę | D27: 3 | E27: % aktualnego HP | F27: Słabsze niż najsłabszy skill
A28: Walka (Combat) | B28: Ogłuszenie z procka (afiks) | C28: Czas trwania | D28: 1 | E28: tura
A29: Walka (Combat) | B29: Afiksy poison_chance/stun_chance | C29: Zakres na broni/pancerzu | D29: 1-7 | E29: %
A30: Walka (Combat) | B30: Afiks strong_vs_hero | C30: Zakres bonusu (PvP/GvG) | D30: 5-20 | E30: %
A31: Walka (Combat) | B31: Miecz - Podwójny Cios | C31: Moc drugiego ciosu | D31: 50 | E31: % głównego ciosu | F31: double_strike_chance
A32: Walka (Combat) | B32: Anti-cheat | C32: Min. czas między walkami | D32: 1300 | E32: ms | F32: Rate limit backend
A33: Walka (Combat) | B33: Auto-Chain | C33: Opóźnienie po wygranej | D33: 700 | E33: ms
A34: Walka (Combat) | B34: Auto-Chain | C34: Kara czasowa po przegranej | D34: 3000 | E34: ms
A35: Walka (Combat) | B35: Walka grupowa (over-level) | C35: Liczba potworów naraz | D35: 3-4 | E35: szt.
A36: Walka (Combat) | B36: Walka grupowa (over-level) | C36: Kara do sumy nagród | D36: -66 (x0.33) | E36: %
A37: Walka (Combat) | B37: Mikstury Łowcy Potworów | C37: Bonus obrażeń (S/M/L) | D37: 5 / 10 / 15 | E37: %
A38: Walka (Combat) | B38: Mikstury Łowcy Potworów | C38: Czas trwania (S/M/L) | D38: 1 / 3 / 6 | E38: h
A39: Walka (Combat) | B39: Wojna Gildii | C39: Limit rund starcia | D39: 40 | E39: rund
A40: Walka (Combat) | B40: Wojna Gildii | C40: Rozmiar drużyny wojennej | D40: 5 | E40: postaci
A41: Dungeony | B41: Klucze / Multi-Dungeon | C41: Mnożniki wypraw | D41: 1x / 3x / 5x | E41: krotność kluczy
...

Sheet Reguły Tekstowe
A1: Reguły Tekstowe / Jakościowe
A2: Zasady projektowe, procesy, ograniczenia i zapisy prawne nie dające się sprowadzić do liczby
A4: Moduł | B4: Mechanika | C4: Reguła / Opis | D4: Typ
A5: Achievements & Kolekcje | B5: Architektura eventowa | C5: System oparty w całości na asynchronicznych eventach (MonsterDefeated -> AchievementProgressed -> toast UI). | D5: Proces
A6: Achievements & Kolekcje | B6: Hierarchia osiągnięć | C6: Osiągnięcia mogą mieć 'Parent ID', tworząc łańcuchy trudności (Tier I/II). | D6: Zasada projektowa
A7: Achievements & Kolekcje | B7: Tytuły | C7: Gracz wybiera jeden zdobyty tytuł do wyświetlania na stałe, aż do zmiany. | D7: Zasada projektowa
A8: Achievements & Kolekcje | B8: Warunki kontekstowe | C8: Osiągnięcia filtrowane przez warunki JSON (np. tylko konkretny typ/ranga potwora). | D8: Proces
A9: Kowal (Blacksmith) | B9: Scalenie domen | C9: Kowal łączy dawne osobne funkcje Brońmistrza i Zbrojmistrza w jeden widok. | D9: Zasada projektowa (refaktor)
A10: Kowal (Blacksmith) | B10: Podział funkcji | C10: Wiedźma odpowiada wyłącznie za crafting mikstur, Kowal za broń/zbroję. | D10: Zasada projektowa
A11: Postacie (Characters) | B11: Unikalność nazwy | C11: Nazwa postaci musi być unikalna w całej grze. | D11: Ograniczenie
A12: Postacie (Characters) | B12: Przedmiot startowy | C12: Każda nowa postać dostaje 'Zardzewiały Miecz' do plecaka. | D12: Zasada projektowa
A13: Postacie (Characters) | B13: Blokada wieloosobowa | C13: Gracz może mieć aktywną tylko jedną postać jednocześnie w sesji. | D13: Bezpieczeństwo
A14: Postacie (Characters) | B14: Idempotencja nagród | C14: Nagrody z walki chronione kluczem idempotency, by uniknąć podwójnego naliczenia. | D14: Bezpieczeństwo
A15: Walka (Combat) | B15: Inicjatywa | C15: Ustalana na bazie AGI obu stron - decyduje kto atakuje pierwszy. | D15: Proces
... A83: Roadmap | B83: Faza 18 - Ekonomia 2.0 | C83: Zawody zbierackie/wytwórcze i ewolucja przedmiotów - planowana. | D83: Status

Sheet Poziomy i Progresja
A1: Poziomy i Progresja
A2: Bramki poziomowe dostępu do modułów oraz krzywa wymaganego XP (formuła z docs/modules/characters.md)
A4: Bramki poziomowe (wymagany poziom postaci)
A5: Moduł / Funkcja | B5: Wymagany poziom
A6: Tablica Wyzwań (Questy) | B6: 5
A7: Gildia | B7: 10
A8: Arena PvP / Sklep Gladiatora | B8: 15
A9: Lustro (Profil + Wiedźma) | B9: 30
A12: Krzywa wymaganego XP i punktów rozwoju wg poziomu (1-99)
A13: Poziom | B13: Wymagane XP (formuła) | C13: Punkty Postaci (skumulowane) | D13: Punkty Umiejętności (skumulowane)
A14: 1 | B14: =15*A14^2+50*A14+0.15*A14^4.1+IF(A14>85,0.025*(A14-85)^5.5,0) -> 65.15 | C14: =10+(A14-1)*3 -> 10 | D14: =(A14-1)*3 -> 0
A15: 2 | B15: =15*A15^2+50*A15+0.15*A15^4.1+IF(A15>85,0.025*(A15-85)^5.5,0) -> 162.57226 | C15: =10+(A15-1)*3 -> 13 | D15: =(A15-1)*3 -> 3
A16: 3 | B16: =15*A16^2+50*A16+0.15*A16^4.1+IF(A16>85,0.025*(A16-85)^5.5,0) -> 298.5609 | C16: =10+(A16-1)*3 -> 16 | D16: =(A16-1)*3 -> 6
A17: 4 | B17: =15*A17^2+50*A17+0.15*A17^4.1+IF(A17>85,0.025*(A17-85)^5.5,0) -> 484.11002 | C17: =10+(A17-1)*3 -> 19 | D17: =(A17-1)*3 -> 9
A18: 5 | B18: =15*A18^2+50*A18+0.15*A18^4.1+IF(A18>85,0.025*(A18-85)^5.5,0) -> 735.12053 | C18: =10+(A18-1)*3 -> 22 | D18: =(A18-1)*3 -> 12
A19: 6 | B19: =15*A19^2+50*A19+0.15*A19^4.1+IF(A19>85,0.025*(A19-85)^5.5,0) -> 1072.5473 | C19: =10+(A19-1)*3 -> 25 | D19: =(A19-1)*3 -> 15
A20: 7 | B20: =15*A20^2+50*A20+0.15*A20^4.1+IF(A20>85,0.025*(A20-85)^5.5,0) -> 1522.5153 | C20: =10+(A20-1)*3 -> 28 | D20: =(A20-1)*3 -> 18
A21: 8 | B21: =15*A21^2+50*A21+0.15*A21^4.1+IF(A21>85,0.025*(A21-85)^5.5,0) -> 2116.4151 | C21: =10+(A21-1)*3 -> 31 | D21: =(A21-1)*3 -> 21
A22: 9 | B22: =15*A22^2+50*A22+0.15*A22^4.1+IF(A22>85,0.025*(A22-85)^5.5,0) -> 2890.9861 | C22: =10+(A22-1)*3 -> 34 | D22: =(A22-1)*3 -> 24
A23: 10 | B23: =15*A23^2+50*A23+0.15*A23^4.1+IF(A23>85,0.025*(A23-85)^5.5,0) -> 3888.3881 | C23: =10+(A23-1)*3 -> 37 | D23: =(A23-1)*3 -> 27
A24: 11 | B24: =15*A24^2+50*A24+0.15*A24^4.1+IF(A24>85,0.025*(A24-85)^5.5,0) -> 5156.2663 | C24: =10+(A24-1)*3 -> 40 | D24: =(A24-1)*3 -> 30
A25: 12 | B25: =15*A25^2+50*A25+0.15*A25^4.1+IF(A25>85,0.025*(A25-85)^5.5,0) -> 6747.8092 | C25: =10+(A25-1)*3 -> 43 | D25: =(A25-1)*3 -> 33
... A112: 99 | B112: =15*A112^2+50*A112+0.15*A112^4.1+IF(A112>85,0.025*(A112-85)^5.5,0) -> 23015965 | C112: =10+(A112-1)*3 -> 304 | D112: =(A112-1)*3 -> 294
A113: Źródło formuły XP: docs/modules/characters.md, sekcja 'Poziomy i XP'. Formuła: 15*L² + 50*L + 0.15*L^4.1 + (L>85 ? 0.025*(L-85)^5.5 : 0). Poziom max = 99 (docs/modules/world_boss.md).

Sheet Walka - Parametry
A1: Walka — Parametry Liczbowe
A2: Twarde limity, skalowanie potworów i formuły zasobów z docs/modules/combat.md
A4: Twarde limity (hard cap) w walce
A5: Parametr | B5: Wartość (%)
A6: Krytyk - hard cap (gracz) | B6: 100
A7: Krytyk - hard cap (potwór) | B7: 30
A8: Unik (dodge) - hard cap | B8: 30
A10: Skalowanie statystyk potworów wg różnicy poziomów (formuła)
A11: Różnica poziomów (gracz - potwór) | B11: Mnożnik staty potwora
A12: 0 | B12: =1+A12*0.1 -> 1
A13: 1 | B13: =1+A13*0.1 -> 1.1
A14: 2 | B14: =1+A14*0.1 -> 1.2
A15: 3 | B15: =1+A15*0.1 -> 1.3
A16: 4 | B16: =1+A16*0.1 -> 1.4
A17: 5 | B17: =1+A17*0.1 -> 1.5
A18: 6 | B18: =1+A18*0.1 -> 1.6
A19: 7 | B19: =1+A19*0.1 -> 1.7
A20: 8 | B20: =1+A20*0.1 -> 1.8
A21: 9 | B21: =1+A21*0.1 -> 1.9
A22: 10 | B22: =1+A22*0.1 -> 2
A23: 11 | B23: =1+A23*0.1 -> 2.1
... A32: 20 | B32: =1+A32*0.1 -> 3
A34: Waga atrybutów wg typu broni (getAttributeAttackBonus)
A35: Broń | B35: STR (waga) | C35: INT (waga) | D35: AGI (waga)
A36: Miecz (sword) | B36: 1 | C36: 0 | D36: 1
A37: Topór (axe) | B37: 2 | C37: 0 | D37: 0
A38: Łuk (bow) | B38: 1 | C38: 0 | D38: 1
A39: Sztylet (dagger) | B39: 1 | C39: 0 | D39: 1
A40: Dzwon (bell) | B40: 1 | C40: 1 | D40: 0
A41: Różdżka (wand) | B41: 0 | C41: 2 | D41: 0
A42: Pięści (barehands) | B42: 2 | C42: 0 | D42: 0
A44: Składowe formuł zasobów gracza (HP vs Mana)
A45: Składowa | B45: HP (pkt) | C45: Mana (pkt)
A46: Baza | B46: 100 | C46: 50
A47: Za punkt atrybutu (VIT / INT) | B47: 15 | C47: 10
A48: Za poziom postaci | B48: 5 | C48: 3

Sheet Ekonomia i Ceny
A1: Ekonomia i Ceny
A2: Opłaty rynkowe, koszty zwojów, dostępu do Lustra i mikstur
A4: Opłata za wystawienie oferty na Rynku (wg czasu trwania)
A5: Czas wystawienia | B5: Opłata (złoto)
A6: 24h | B6: 100
A7: 48h | B7: 250
A8: 72h | B8: 500
A9: Dodatkowo: 5% prowizji systemowej od ceny sprzedaży przy każdej transakcji.
A11: Koszty w Gemach (waluta premium)
A12: Pozycja | B12: Koszt (gemy)
A13: Zwój Areny Walki | B13: 30
A14: Zwój Resetu Umiejętności | B14: 50
A15: Zwój Resetu Atrybutów | B15: 50
A16: Dodatkowy slot magazynu gracza | B16: 50
A17: Reset atrybutów (Profil) | B17: 50
A18: Zwój Pełnego Resetu | B18: 90
A19: Dostęp do Lustra (7 dni) | B19: 200
A20: Dostęp do Lustra można też opłacić 5 000 000 złota zamiast 200 gemów.
A22: Mikstury (rework 2026-08-02) — Rozmiar S / M / L
A23: Rozmiar | B23: Bonus (%) | C23: Czas trwania (h)
A24: S (Mała) | B24: 5 | C24: 1
A25: M (Średnia) | B25: 10 | C25: 3
A26: L (Duża) | B26: 15 | C26: 6

Sheet Pety
A1: Pety — Tiery, Wykluwanie i Fuzja
A2: docs/modules/pets.md — 6 tierów, macierz wyklucia, szanse i koszty fuzji
A4: Tiery Chowańców
A5: Tier | B5: Nazwa | C5: Czas wyklucia (h) | D5: Norma poziomowa (%) | E5: Karmienie od poziomu
A6: T1 | B6: Pospolity | C6: 1 | D6: 100 | E6: 0
A7: T2 | B7: Zwykły | C7: 1.5 | D7: 130 | E7: 15
A8: T3 | B8: Nietypowy | C8: 2 | D8: 160 | E8: 30
A9: T4 | B9: Rzadki | C9: 2.5 | D9: 190 | E9: 45
A10: T5 | B10: Epicki | C10: 3 | D10: 220 | E10: 60
A11: T6 | B11: Legendarny | C11: 4 | D11: 250 | E11: 75
A23: Macierz Wyklucia (Jajko -> Pet, % szansy na tier wynikowy)
A24: Jajko \ Pet | B24: T1 | C24: T2 | D24: T3 | E24: T4 | F24: T5 | G24: T6
A25: T1 | B25: 100 | C25: 0 | D25: 0 | E25: 0 | F25: 0 | G25: 0
A26: T2 | B26: 25 | C26: 75 | D26: 0 | E26: 0 | F26: 0 | G26: 0
A27: T3 | B27: 10 | C27: 25 | D27: 65 | E27: 0 | F27: 0 | G27: 0
A28: T4 | B28: 0 | C28: 10 | D28: 45 | E28: 45 | F28: 0 | G28: 0
A29: T5 | B29: 0 | C29: 0 | D29: 20 | E29: 60 | F29: 20 | G29: 0
A30: T6 | B30: 0 | C30: 0 | D30: 0 | E30: 35 | F30: 60 | G30: 5
A42: Fuzja (2 pety tego samego tieru -> 1 wyższego)
A43: Fuzja | B43: Szansa bazowa (%) | C43: Szansa max z bonusem (%) | D43: Koszt (złoto)
A44: T1+T1 -> T2 | B44: 80 | C44: 100 | D44: 100
A45: T2+T2 -> T3 | B45: 65 | C45: 85 | D45: 250
A46: T3+T3 -> T4 | B46: 50 | C46: 70 | D46: 500
A47: T4+T4 -> T5 | B47: 35 | C47: 55 | D47: 1000
A48: T5+T5 -> T6 | B48: 20 | C48: 40 | D48: 2000
A49: Bonus dojrzałości = (growth_stage_A+growth_stage_B) x 3.3333% (max 6 stopni = +20%).
A51: Warianty porażki fuzji (losowane wg wagi)
A52: Wariant porażki | B52: Szansa (%)
A53: Brak utraty (no_loss) | B53: 43
A54: Cofnięcie 1 peta (devolve_one) | B54: 25
A55: Cofnięcie obu (devolve_both) | B55: 20
A56: Utrata 1 peta (lose_one) | B56: 10
A57: Utrata obu (lose_both) | B57: 2

Sheet Rzemiosło i Ulepszenia
A1: Rzemiosło i Ulepszenia
A2: Rzadkość craftingu, krzywa szans zaklęć oraz ulepszanie +0..+9
A4: Szansa na rzadkość przy Craftingu (Kowal/Wiedźma)
A5: Rzadkość | B5: Szansa (%)
A6: Common | B6: 70
A7: Uncommon | B7: 20
A8: Rare | B8: 8
A9: Epic | B9: 1.9
A10: Legendary | B10: 0.1
A13: Zaklinanie u Czarodzieja/Wiedźmy — szansa sukcesu wg liczby bonusów
A14: Liczba bonusów na przedmiocie | B14: Szansa sukcesu (%)
A15: 1 | B15: 75
A16: 2 | B16: 50
A17: 3 | B17: 40
A18: 4 | B18: 30
A19: 5 | B19: 20
A22: Ulepszanie w Kuźni (+0 do +9) — dane dostępne w dokumentacji
A23: Poziom ulepszenia | B23: Opis szansy wg dokumentacji
A24: +0 -> +1 | B24: ~95% (jedyna dokładna wartość podana wprost w docs/modules/upgrades.md)
A25: +1 -> +5 | B25: Szansa systematycznie maleje - dokumentacja nie podaje dokładnych % dla poszczególnych poziomów
A26: +5 i wyżej | B26: Szansa drastycznie maleje - celowy 'gold sink'; brak dokładnych wartości w dokumentacji
A27: Celowo nie dorysowano pełnej krzywej % dla +2..+9 — źródło (docs/modules/upgrades.md) opisuje ją tylko jakościowo, a wymyślanie liczb wprowadziłoby dane, których nie ma w dokumentacji.

Sheet Nagrody Cykliczne
A1: Nagrody Cykliczne
A2: Rankingi Tygodniowe i nagrody World Bossa wg miejsca w rankingu
A4: Rankingi Tygodniowe (6 kategorii, reset co poniedziałek)
A5: Miejsce | B5: Nagroda (gemy)
A6: 1 | B6: 300
A7: 2 | B7: 250
A8: 3 | B8: 200
A9: 4-10 | B9: 100
A12: Nagrody World Bossa (rozliczenie co godzinę, Top 9)
A13: Miejsce | B13: Gemy | C13: Klucze do lochu
A14: 1 | B14: 50 | C14: 5
A15: 2-3 | B15: 30 | C15: 5
A16: 4-6 | B16: 0 | C16: 3
A17: 7-9 | B17: 0 | C17: 1
A18: 10+ | B18: 0 | C18: 0

Sheet Dungeony i Multi
A1: Dungeony — Tryb Multi-Dungeon
A2: Skalowanie trudności i nagród przy zużyciu wielokrotności kluczy (1x/3x/5x)
A4: Skalowanie statystyk potworów i skrzyń z bossa wg mnożnika
A5: Mnożnik wyprawy | B5: Staty potworów (%) | C5: Skrzynie z bossa (min) | D5: Skrzynie z bossa (max)
A6: 1x | B6: 100 | C6: 1 | D6: 3
A7: 3x | B7: 135 | C7: 3 | D7: 9
A8: 5x | B8: 170 | C8: 5 | D8: 15
A9: Zakres skrzyń dla 3x obliczony proporcjonalnie do bazowego zakresu 1-3 (dokumentacja wprost potwierdza tylko przykład dla 5x = 5-15 skrzyń, reguła: bazowy zakres x mnożnik kluczy).

Sheet Roadmapa
A1: Roadmapa Rozwoju
A2: Status 18 faz rozwoju gry wg docs/roadmap.md
A4: Fazy Rozwoju
A5: Faza | B5: Nazwa | C5: Status
A6: 1 | B6: Solidne Podstawy i Rdzeń Walki | C6: Zakończona
A7: 2 | B7: Zarządzanie Ekwipunkiem | C7: Zakończona
A8: 3 | B8: Kuźnia i Ulepszenia (Metin2 Style) | C8: Zakończona
A9: 4 | B9: Czarodziej i Typy Potworów | C9: Zakończona
A10: 5 | B10: System Administracyjny (GUI) i Combat Power | C10: Zakończona
A11: 6 | B11: Czarownica i Warzenie Mikstur | C11: Zakończona
A12: 7 | B12: Gospodarka, Market i Poczta | C12: Zakończona
A13: 8 | B13: Aspekty Społecznościowe i Czat Globalny | C13: Zakończona
A14: 9 | B14: Rzemiosło i Zbieractwo (Crafting) | C14: Zakończona
A15: 10 | B15: Doskonalenie UI, Skalowalność i Optymalizacja | C15: Zakończona
A16: 11 | B16: Rozszerzenie PvE i Endgame (World Boss & Dungeons) | C16: Zakończona
A17: 12 | B17: Player vs Player (PvP) i Wojny Gildii | C17: Zakończona
... A23: 18 | B23: Ekonomia 2.0 i System Zawodów | C23: Planowana
A26: Podsumowanie statusu
A27: Zakończone | B27: =COUNTIF(C6:C23,"Zakończona") -> 16
A28: Planowane | B28: =COUNTIF(C6:C23,"Planowana") -> 2
